Workbook
Name Environment_rediness_for_Dev_QA: 'Complexity Summary'!$D$17

Sheet Overview
B2: 8000 - EXL/F&A Reports automation 2 (Advisory-17 Reports)
B3: KPMG Proposed Start Date: | C3: TBD
B4: KPMG Defined Deadline: | C4: TBD
B5: Calculated Complexity: | C5: Complex
B6: SLA Duration: | C6: TBD
B7: Calculated End Date: | C7: TBD
B8: Scope of Services: | C8: Develop, Test, Debug, Fix, Deploy
B9: Dependencies: | C9: Business Shared Drive, Sharepoint, Microsoft Excel, Outlook, HANA
B10: Comments/Notes:

Sheet Complexity Summary
B2: S.No. | C2: Use Case Attribute | D2: Value | E2: Story Points | H2: Legends | I2: Input Needed
B3: 1 | C3: =Rules!C4 -> Objects - Total Screens/UI | D3: No Objects | E3: =VLOOKUP(D3,Rules!E4:F8,2,FALSE) -> 0 | I3: Computed Value
B4: 2 | C4: =Rules!C9 -> Business/Validation - Decisions/Rules | D4: 1 to 12 | E4: =VLOOKUP(D4,Rules!E9:F13,2,FALSE) -> 1
B5: 3 | C5: =Rules!C14 -> Interface DB - DB Queries | D5: Query Weightage 1 to 15 | E5: =VLOOKUP(D5,Rules!E14:F18,2,FALSE) -> 1
B6: 4 | C6: =Rules!C19 -> Process Design - Total Process Steps | D6: 51 to 60 | E6: =VLOOKUP(D6,Rules!E19:F27,2,FALSE) -> 6
B7: 5 | C7: =Rules!C32 -> File Process - Excel sheets | D7: 1 to 6 Excel Sheets | E7: =VLOOKUP(D7,Rules!E32:F36,2,FALSE) -> 1
B8: 6 | C8: =Rules!C37 -> File Process - Word/Pdf/Power Point | D8: Handling Structured/Semi-Structured/Unstructured Data | E8: =VLOOKUP(D8,Rules!E37:F40,2,FALSE) -> 3
B9: 7 | C9: =Rules!C41 -> Reports Creation/updation - Bot Execution Report/Metrics Report | D9: NA | E9: =VLOOKUP(D9,Rules!E41:F45,2,FALSE) -> 0
B10: 8 | C10: =Rules!C46 -> Exception Handling (Business/System) | D10: 1 to 10 Exceptions | E10: =VLOOKUP(D10,Rules!E46:F50,2,FALSE) -> 1
B11: 9 | C11: =Rules!C55 -> Target Application UI access mode | D11: Direct Access | E11: =VLOOKUP(D11,Rules!E55:F56,2,FALSE) -> 0
B12: 10 | C12: =Rules!C57 -> Automation Scripting - No. of Scripts need to be build | D12: Up to 6 | E12: =VLOOKUP(D12,Rules!E57:F61,2,FALSE) -> 1
B13: 11 | C13: =Rules!C62 -> Reusable Modules | D13: No Reusable Module | E13: =VLOOKUP(D13,Rules!E62:F64,2,FALSE) -> 0
B14: 12 | C14: =Rules!C65 -> API Interfaces - No of Interface in user story | D14: No API Interfaces | E14: =VLOOKUP(D14,Rules!E65:F69,2,FALSE) -> 0
B15: 13 | C15: =Rules!C70 -> Understanding existing automation (atmx) E2E (Enh. only) | D15: No atmx file | E15: =VLOOKUP(D15,Rules!E70:F73,2,FALSE) -> 0
B16: 14 | C16: =Rules!C74 -> Understanding existing Macro/Other Scripts E2E (Enh. only) | D16: No Macro/Other Scripts | E16: =VLOOKUP(D16,Rules!E74:F77,2,FALSE) -> 0
B17: 15 | C17: =Rules!C78 -> Environment Readiness for Dev/QA/Prod | D17: Environment Readiness for Dev/QA/Prod | E17: =VLOOKUP(D17,Rules!E78:F79,2,FALSE) -> 1
B18: 16 | C18: =Rules!C80 -> Solution Design (SDD) | D18: Multi Bot Architecture without interaction with each other | E18: =VLOOKUP(D18,Rules!E80:F83,2,FALSE) -> 2 | F18: .
B19: 17 | C19: =Rules!C84 -> Test Case Document & QAT | D19: Test Case up to 20 | E19: =VLOOKUP(D19,Rules!E84:F88,2,FALSE) -> 1
D20: Total Story Points | E20: =ROUND(SUM(E3:E19),0) -> 18
D22: Use Case Complexity | E22: =IF(E20/E25 <=D25,C25,IF(E20/E25<=D26,C26,IF(E20/E25<=D27,C27,#REF!))) -> Medium
C24: T-Shirt Size Build Services | D24: Multiplier | E24: Story Points
C25: Simple | D25: 1 | E25: 15
C26: Medium | D26: 2 | E26: 30
C27: Complex | D27: 4 | E27: 60

Sheet TaskList
B1: Process Description | C1: Task Description | D1: Sub Tasks | E1: Comments | F1: Objects - Total Screens/UI | G1: Business/Validation - Decisions/Rules | H1: Interface DB - DB Queries | I1: Process Design - Total Process Steps | J1: File Process - Excel sheets | K1: File Process - Word/Pdf/Power Point | L1: Reports Creation/updation - report Execution Report/Metrics Report | M1: Exception Handling (Business/System) | N1: Target Application UI access mode | O1: Automation Scripting - No. of Scripts need to be build | P1: Reusable Modules needed | Q1: API Interfaces - No of Interface in user story
B2: Refresh Engagement Dashboard.
B3: Updating Engagment Summary Dashboard – Recievable Report | C3: Get Input Recievable detail File | D3: 1.Check for Network drive access: \\Usmdcflex009\KSD\department\BET Technology Network Drive. 2.if no access send an exception email. | G3: 1 | I3: 3
D4: 1.Check Recievable detail File from-\\Usmdcflex009\KSD\department\BET Technology Network Drive 2.If zip file (Receivables Report_ YYYY-MM-DD.zip) file not found send exception 3.If file found copy and Paste that zip file in Local folder. | G4: 1 | I4: 3
C9: Copy master Template to Inprogress folder | D9: 1.Unzip the folder and Open Recievable detail file. | I9: 10 | J9: 1
D10: 1.Copy Engagement Summary master Template from templates Folder to Inprogress Folder 2.Open Master template file and switch to recievable report sheet. 3.Check if headers are same for both template and Recievable detail File. 4.If not matching,Reorder or rename columns in the Receivable Detail file based on template structure. 5.Add new colums from Receivable file if not present in Template file. 6.Save and close FIle. 7.Connect to recievable report file as database. 8.Copy data whose Engagement Function is Tax only.
C11: Excel Manipulation | D11: 1.Add a new column with name Invoice Aging days in File. 2.This column will calculate the difference between Bill Clearing date and Billing Date. 3. Convert the difference into days and paste the data in Master template file. 4.Add a new coulmn with name Average Invoice Aging Days. 5.Calculate the average out of Invoice Aging Days by Clinet Name. 6.Go to Column B and convert data to Number. 7.Go to Column H and remove duplicates. 8.Go to Coulmn Q and sort data from largest to smallest. 9.Save File. | I11: 2 | J11: 1
B15: Update Engagement Summary Dashboard – Open Engagement | C15: Get Input Engagement Summary File. | D15: 1.Check Engagement summary File from-\\Usmdcflex009\KSD\department\BET Technology Network Drive 2.If file not found send exception 3.If file found copy and Paste that zip file in sub folder | I15: 3
C21: Excel Manipulation | D21: 1.Unzip the file and Connect to Engagement Summary file as Database. 2.Copy data whose Current Engagement Profit Center : Function Desc is Tax group only. | I21: 2
C23: Macro-Updating data from Engagement Summary File to Master Template File. | D23: 1.Open Engagement Summary Master Template File. 2.Switch to Engagement Summary Sheet in Master Template. 3.paste Copied data fromRae report of engagement summary to Engagement Summary sheet in Master Template. 4.Select Column C and convert it to a Number. 5.Select Column D and remove duplicates. 6.Select Column D and convert data into Number. 7.Go to Column G and paste Special by divide. 8.Go to Column Z and Select percentage to dispaly data in correct format. 9.Go to column A1 and upfdate todays date as last refresh date. 10.Save the file. | I23: 13
B25: Macro-Updating Engagement numbers in Engagement Summary report sheet. | C25: Updating Engagement numbers in Engagement Summary report sheet for getting remaining fields updated.. | D25: 1 copies all values from Open Engagements!D5:D(last row). 2.and pastes them into Engagement Summary Report!H7 downward, 3.reads all Engagement IDs from “Open Engagements” (column D, row 5 down). 4. compares them to the existing IDs in “Engagement Summary Report” (column H, row 6 down). 5.adds only the new ones to column H with a note in column B—while skipping blanks, skipping duplicates. 6.Save the file. | I25: 6
B27: Updating Engagement numbers in Closeout Pivot sheet. | C27: Updating Engagement numbers in Closeout Pivot sheet for getting Code change and notes fields updated. | D27: 1.Values will be uodated for them whose status is showing as closed. | I27: 1
B28: Billing and Cash Drive Sheet | C28: Updating partner wise data from Recievables report sheet and engagement summary sheet in the Billing and cash drive sheet. | D28: 1.Copy all Partner names which will be taken form Recievable report. 2.Remove duplicate names from Partners. 3. paste those partner names to Billing and cash drive Sheets. 4.Apply formulas for remaining cloumn to get unbilled total, cash total etc. 5.At the end of the sheet apply formulas to all the cloumns to find total. 6.Repeat this for other two sheets. | I28: 6 | J28: 4
B29: Updating all three sheets of data to Sharepoint | D29: 1.Create three new workbooks for Engagement summaey Dashboard , Billing and cash drive and Recievables report. 2.Copy data from each sheet and paste it in workbooks. 3.Update all three excel workbooks to Sharepoint.
B30: Extracting details from Engagement letters
B31: Extracting details from Engagement letters and SAN Free range from Mail attachment. | C31: Download engagement report files from sharepoint. | D31: 1.Validate sharepoint link check for access and files. 2.If no Accessand no files send exception to Business. 3.loop through each row and Check if flag Open, then download the engagement letter and email atatchment. 4.Change the Flag to InProgress. | G31: 1 | I31: 4
C32: Extract fee details from Engagement letters | D32: 1.Copy all Engagement letters and Email Attachments from downloads to Local folder. 2.Loop Through each file of pdf Attachment. 3.Send Engagement letter to LLM and extract the required details from prompts. 4.Also give prompts to what fields to be extracted with keywords. 5.Update the extracted fields from engagement letters to template file. 6.Save the file. | I32: 6
C33: Extract SAN FEE Range from email Attachments | D33: 1.Download Email attachment from Sharepoint list. 2.Get the file name(Engagement Number). 3.Open each atatchment and extaract body from email attachment to a string. 4.Extract required SAN FEE RANGE from the string. 5.Open Template file and update details of the extracted san fee range with the Engagement Number. 6.Close the outlook Attachment. 7.Change the flag to complete in Sharepoint. | I33: 7
C34: Upload file in Sharepoint.

Sheet Extension_Config
A1: Original Name | B1: Replacement Value
A2: ä | B2: a
A3: A.B. | B3: AB
A4: A/B | B4: AB
A5: Aktiebolag | B5: AB
A6: Company | B6: Co.
A7: Corporation | B7: Corp
A8: Gesellschaft mit beschränkter Haftung | B8: Gmbh
A9: Gmbh & Co | B9: Gmbh
A10: Incorporated | B10: Inc.
A11: Kommanditgesellschaft | B11: KG
A12: ltd | B12: Limited
... A36: društvo s ograničenom odgovornošću | B36: doo

Sheet Assumptions
B2: S.No | C2: Assumption | D2: remarks
B3: 1
B4: 2

Sheet Queries
B2: S.No | C2: Queries
B3: 1

Sheet Rules
B2: Rules to Define Automation Complexity
B3: S. No. | C3: Use Case Attribute | D3: Attribute Weightage | E3: Parameters | F3: Parameter Weightage | G3: Note
B4: 1 | C4: Objects - Total Screens/UI | D4: =ROUND(1/MAX(B:B),3) -> 0.053 | E4: No Objects | F4: 0 | G4: Every 8 total screening/UI, 1 story point to be added
E5: 1 to 8 | F5: 1
E6: 9 to 16 | F6: 2
E7: 17 to 24 | F7: 3
E8: 25 to 32 | F8: 4
B9: 2 | C9: Business/Validation - Decisions/Rules | D9: =ROUND(1/MAX(B:B),3) -> 0.053 | E9: No Rules | F9: 0 | G9: Every 12 Business/Validation - Decisions/Rules, 1 story point to be added
E10: 1 to 12 | F10: 1
E11: 13 to 24 | F11: 2
E12: 25 to 36 | F12: 3
E13: 37 to 48 | F13: 4
B14: 3 | C14: Interface DB - DB Queries | E14: No Queries | F14: 0 | G14: Every 15 Query Weightage, 1 story point to be added | H14: Weightage of the Query | I14: Query Description | J14: No of queries | K14: Total Weightage
E15: Query Weightage 1 to 15 | F15: 1 | H15: 1 | I15: Queries using 1 to 3 tables | J15: 5 | K15: =J15*H15 -> 5
E16: Query Weightage 16 to 30 | F16: 2 | H16: 2 | I16: Queries using 4 to 8 tables | J16: 1 | K16: =J16*H16 -> 2
E17: Query Weightage 31 to 45 | F17: 3 | H17: 3 | I17: Queries using more than 8 tables | J17: 1 | K17: =J17*H17 -> 3
E18: Query Weightage more than 45 | F18: 4 | K18: =SUM(K15:K17) -> 10
B19: 4 | C19: Process Design - Total Process Steps | E19: NA | F19: 0 | G19: Every 10 Process Design - Total Process Steps, 1 story point to be added
E20: 1 to 10 | F20: 1
E21: 11 to 20 | F21: 2
E22: 21 to 30 | F22: 3
E23: 31 to 40 | F23: 4
E24: 41 to 50 | F24: 5
E25: 51 to 60 | F25: 6
E26: 61 to 70 | F26: 7
E27: 71 to 80 | F27: 8
B28: 5 | C28: Applications Involved - No. of Systems | D28: =ROUND(1/MAX(B:B),3) -> 0.053 | E28: NA | F28: 0 | G28: Removed
E29: 1 to 6 | F29: 1
E30: 7 to 10 | F30: 2
E31: 11 to 15 | F31: 4
B32: 6 | C32: File Process - Excel sheets | D32: 0.077 | E32: NA | F32: 0 | G32: Every 6 File Process - Excel sheets, 1 story point to be added
E33: 1 to 6 Excel Sheets | F33: 1
E34: 7 to 12 Excel Sheets | F34: 2
E35: 13 to 18 Excel Sheets | F35: 3
E36: 19 to 24 Excel Sheets | F36: 4
B37: 7 | C37: File Process - Word/Pdf/Power Point | D37: 0.077 | E37: NA | F37: 0 | G37: Structured Data: 1. Simple fixed field/location/editable text(Ex: Invoice number, date etc.) 2. No Images Semi-Structured Data: 1. Handling clear Images(Ex:Signatures,stamp etc.) 2. Identify free editable text Structured/Semi-Structured/Unstructured Data: 1. Working on Unstructured Data/Form elements 2. Working on Power point file[Copy data from word to PPT vice versa]
E38: Handling Structured Data | F38: 1
E39: Handling Semi-Structured Data | F39: 2
E40: Handling Structured/Semi-Structured/Unstructured Data | F40: 3
B41: 8 | C41: Reports Creation/updation - Bot Execution Report/Metrics Report | D41: 0.077 | E41: NA | F41: 0 | G41: Every 2 Reports Creation/updation - Bot Execution Report/Metrics Report, 1 story point to be added
...
